<?xml version="1.0"?>
<robot xmlns:xacro="http://www.ros.org/wiki/xacro" name="robot">

    <link
    name="base">
    <visual>
      <origin
        xyz="0 0 0"
        rpy="0 0 0" />
      <geometry>
         <cylinder radius="0.2" length="0.5"/>
      </geometry>
    </visual>
  </link>

  <link
    name="link1">
    <visual>
      <origin
        xyz="0 0.5 0"
        rpy="0 0 0" />
      <geometry>
        <cylinder radius="0.2" length="0.5"/>
      </geometry>
    </visual>
  </link>
  <joint
    name="joint1"
    type="revolute">
    <origin
      xyz="0 0 0.5"
      rpy="0 0 0" />
    <parent
      link="base" />
    <child
      link="link1" />
    <axis
      xyz="0 0 1" />
      <limit lower="-1" upper="1"
        effort="100" velocity="100"/>
  </joint>
  <link
    name="link2">
    <visual>
      <origin
        xyz="0 0 0"
        rpy="0 0 0" />
      <geometry>
        <cylinder radius="0.2" length="0.5"/>
      </geometry>
    </visual>
  </link>
  <joint
    name="joint2"
    type="revolute">
    <origin
      xyz="0 0 1"
      rpy="0 0 0" />
    <parent
      link="link1" />
    <child
      link="link2" />
    <axis
      xyz="0 0 1" />
    <limit lower="-1" upper="1"
        effort="100" velocity="100"/>
  </joint>
  <link
    name="link3">
    <visual>
      <origin
        xyz="0 0 0"
        rpy="0 0 0" />
      <geometry>
        <cylinder radius="0.2" length="0.5"/>
      </geometry>
    </visual>
  </link>
  <joint
    name="joint3"
    type="revolute">
    <origin
      xyz="0 0 1.5"
      rpy="0 0 0" />
    <parent
      link="link2" />
    <child
      link="link3" />
    <axis
      xyz="0 0 1" />
     <limit lower="-1" upper="1"
        effort="100" velocity="100"/>
  </joint>

    <ros2_control name="testControl" type="system">
          <hardware>
            <plugin>test_hardware_interface_wrappers/TestableJointSystem</plugin>
          </hardware>
         <joint name="joint1">
                <command_interface name="position"/>
                <command_interface name="velocity"/>
                <state_interface name="position"/>
                <state_interface name="velocity"/>
                <state_interface name="effort"/>
         </joint>
            <joint name="joint2">
                <command_interface name="position"/>
                <command_interface name="velocity"/>
                <state_interface name="position"/>
                <state_interface name="velocity"/>
                <state_interface name="effort"/>
            </joint>
          <joint name="joint3">
                <command_interface name="position"/>
                <command_interface name="velocity"/>
                <state_interface name="position"/>
                <state_interface name="velocity"/>
                <state_interface name="effort"/>
            </joint>
        </ros2_control>
</robot>
